Workbook
Name Slicer_Category: #N/A
Name Slicer_Has_Duplicate_ID: #N/A
Name Slicer_Status: #N/A

Sheet Summary
B2: Audit Reconciliation — Summary
B3: General Ledger vs Bank Statement · sve KPI vrijednosti su formule vezane na sheet 'Reconciliation' i azuriraju se automatski
B4: ="Report generated: "&TEXT(TODAY(),"DD.MM.YYYY")
B6: Total Transactions | D6: Matched | F6: Exceptions | H6: Duplicates
B7: =COUNTA(Reconciliation!$A$2:$A$996) | D7: =COUNTIF(Reconciliation!$M$2:$M$996,"Matched") | F7: =COUNTIF(Reconciliation!$N$2:$N$996,"Yes") | H7: =COUNTIF(Reconciliation!$O$2:$O$996,"Yes")
B10: Only in GL | D10: Only in Bank | F10: Amount Mismatch | H10: Match Rate
B11: =COUNTIF(Reconciliation!$M$2:$M$996,"Only in GL") | D11: =COUNTIF(Reconciliation!$M$2:$M$996,"Only in Bank") | F11: =COUNTIF(Reconciliation!$M$2:$M$996,"Amount Mismatch") | H11: =IFERROR(COUNTIF(Reconciliation!$M$2:$M$996,"Matched")/COUNTA(Reconciliation!$A$2:$A$996),0)
B14: Exception Value | D14: Above Materiality | F14: Largest Exception | H14: Avg Exception
B15: =SUMIF(Reconciliation!$N$2:$N$996,"Yes",Reconciliation!$K$2:$K$996) | D15: =COUNTIFS(Reconciliation!$N$2:$N$996,"Yes",Reconciliation!$K$2:$K$996,">"&$B$18) | F15: =SUMPRODUCT(MAX((Reconciliation!$N$2:$N$996="Yes")*Reconciliation!$K$2:$K$996)) | H15: =IFERROR(SUMIF(Reconciliation!$N$2:$N$996,"Yes",Reconciliation!$K$2:$K$996)/COUNTIF(Reconciliation!$N$2:$N$996,"Yes"),0)
B17: Materiality Threshold (KM) | D17: ← plava brojka je jedina celija koju rucno mijenjas; KPI 'Above Materiality' i kolona N na 'Exceptions' se preracunavaju same
B18: 1000
B21: Breakdown po statusu
B22: Status | C22: Transactions | D22: % of Total | E22: Net Amount | F22: Absolute Value
B23: Matched | C23: =COUNTIF(Reconciliation!$M$2:$M$996,$B23) | D23: =IFERROR($C23/COUNTA(Reconciliation!$A$2:$A$996),0) | E23: =SUMIF(Reconciliation!$M$2:$M$996,$B23,Reconciliation!$J$2:$J$996) | F23: =SUMIF(Reconciliation!$M$2:$M$996,$B23,Reconciliation!$K$2:$K$996)
B24: Only in GL | C24: =COUNTIF(Reconciliation!$M$2:$M$996,$B24) | D24: =IFERROR($C24/COUNTA(Reconciliation!$A$2:$A$996),0) | E24: =SUMIF(Reconciliation!$M$2:$M$996,$B24,Reconciliation!$J$2:$J$996) | F24: =SUMIF(Reconciliation!$M$2:$M$996,$B24,Reconciliation!$K$2:$K$996)
B25: Only in Bank | C25: =COUNTIF(Reconciliation!$M$2:$M$996,$B25) | D25: =IFERROR($C25/COUNTA(Reconciliation!$A$2:$A$996),0) | E25: =SUMIF(Reconciliation!$M$2:$M$996,$B25,Reconciliation!$J$2:$J$996) | F25: =SUMIF(Reconciliation!$M$2:$M$996,$B25,Reconciliation!$K$2:$K$996)
B26: Amount Mismatch | C26: =COUNTIF(Reconciliation!$M$2:$M$996,$B26) | D26: =IFERROR($C26/COUNTA(Reconciliation!$A$2:$A$996),0) | E26: =SUMIF(Reconciliation!$M$2:$M$996,$B26,Reconciliation!$J$2:$J$996) | F26: =SUMIF(Reconciliation!$M$2:$M$996,$B26,Reconciliation!$K$2:$K$996)
B27: TOTAL | C27: =SUM(C23:C26) | D27: =SUM(D23:D26) | E27: =SUM(E23:E26) | F27: =SUM(F23:F26)
B30: Napomene / pretpostavke
B31: • Podaci su sinteticki (generisani u Pythonu, seed=42) — nisu stvarne transakcije.
B32: • Merge je radjen po Transaction_ID (outer join). Prije merge-a je svaka tabela de-duplicirana (keep='first') da jedan ID daje jedan red.
B33: • Amount Mismatch = |Amount_GL - Amount_Bank| > 0.01 (tolerancija na zaokruzivanje).
B34: • 'Duplicates' broji jedinstvene Transaction_ID-eve koji se pojavljuju vise od jednom u GL ili Bank tabeli.
B35: • Bank Statement nema Category/Account — bank-only redovi su oznaceni kao 'Unclassified (Bank only)'.
B36: • Datumi u banci su 0-3 dana kasniji od GL (clearing delay); to nije tretirano kao izuzetak.
B37: • Materiality threshold (1000 KM u celiji B18) je proizvoljno postavljen za demonstraciju — u stvarnoj reviziji izvodi se iz ukupnog prometa ili bilansne sume.
B38: • 'Absolute Value' koristi Abs_Amount da se prihodi i troskovi medjusobno ne ponistavaju.

Sheet Exceptions
A1: Transaction_ID | B1: Date | C1: Category | D1: Account | E1: Description_GL | F1: Description_Bank | G1: Amount_GL | H1: Amount_Bank | I1: Amount | J1: Abs_Amount | K1: Amount_Diff | L1: Abs_Diff | M1: Status | N1: Above_Materiality | O1: Priority | P1: Assigned_To | Q1: Resolution_Notes | R1: Resolved
A2: TXN-00376 | B2: 45360 | C2: Sales Revenue | D2: 4000 | E2: Invoice payment received | F2: INVOICE PAYMENT RECEIV | G2: 18808.11 | H2: 188081.1 | I2: 18808.11 | J2: 18808.11 | K2: -169272.99 | L2: =IFERROR(ABS(K2),"") | M2: Amount Mismatch | N2: =IF(J2>Summary!$B$18,"Yes","No") | O2: =RANK(J2,$J$2:$J$64,0)
A3: TXN-00120 | B3: 45295 | C3: Vendor Payment | D3: 5100 | E3: Contractor fee | F3: CONTRACTOR FEE | G3: -14882.22 | H3: -148822.2 | I3: -14882.22 | J3: 14882.22 | K3: 133939.98 | L3: =IFERROR(ABS(K3),"") | M3: Amount Mismatch | N3: =IF(J3>Summary!$B$18,"Yes","No") | O3: =RANK(J3,$J$2:$J$64,0)
A4: TXN-09008 | B4: 45417 | C4: Vendor Payment | D4: 5100 | E4: Contractor fee | G4: -14623.94 | I4: -14623.94 | J4: 14623.94 | L4: =IFERROR(ABS(K4),"") | M4: Only in GL | N4: =IF(J4>Summary!$B$18,"Yes","No") | O4: =RANK(J4,$J$2:$J$64,0)
A5: TXN-09013 | B5: 45295 | C5: Vendor Payment | D5: 5100 | E5: Supplier invoice | G5: -13985.64 | I5: -13985.64 | J5: 13985.64 | L5: =IFERROR(ABS(K5),"") | M5: Only in GL | N5: =IF(J5>Summary!$B$18,"Yes","No") | O5: =RANK(J5,$J$2:$J$64,0)
A6: TXN-00670 | B6: 45653 | C6: Vendor Payment | D6: 5100 | E6: Contractor fee | F6: CONTRACTOR FEE | G6: -13607.35 | H6: -13.6 | I6: -13607.35 | J6: 13607.35 | K6: -13593.75 | L6: =IFERROR(ABS(K6),"") | M6: Amount Mismatch | N6: =IF(J6>Summary!$B$18,"Yes","No") | O6: =RANK(J6,$J$2:$J$64,0)
A7: TXN-09001 | B7: 45308 | C7: Vendor Payment | D7: 5100 | E7: Vendor payment - materials | G7: -11925.61 | I7: -11925.61 | J7: 11925.61 | L7: =IFERROR(ABS(K7),"") | M7: Only in GL | N7: =IF(J7>Summary!$B$18,"Yes","No") | O7: =RANK(J7,$J$2:$J$64,0)
A8: TXN-09020 | B8: 45436 | C8: Vendor Payment | D8: 5100 | E8: Contractor fee | G8: -11408.77 | I8: -11408.77 | J8: 11408.77 | L8: =IFERROR(ABS(K8),"") | M8: Only in GL | N8: =IF(J8>Summary!$B$18,"Yes","No") | O8: =RANK(J8,$J$2:$J$64,0)
A9: TXN-09002 | B9: 45414 | C9: Vendor Payment | D9: 5100 | E9: Vendor payment - materials | G9: -11345.48 | I9: -11345.48 | J9: 11345.48 | L9: =IFERROR(ABS(K9),"") | M9: Only in GL | N9: =IF(J9>Summary!$B$18,"Yes","No") | O9: =RANK(J9,$J$2:$J$64,0)
A10: TXN-00583 | B10: 45632 | C10: Vendor Payment | D10: 5100 | E10: Vendor payment - materials | F10: VENDOR PAYMENT - MATER | G10: -11115.22 | H10: -11490.6 | I10: -11115.22 | J10: 11115.22 | K10: 375.38 | L10: =IFERROR(ABS(K10),"") | M10: Amount Mismatch | N10: =IF(J10>Summary!$B$18,"Yes","No") | O10: =RANK(J10,$J$2:$J$64,0)
A11: TXN-09021 | B11: 45361 | C11: Vendor Payment | D11: 5100 | E11: Supplier invoice | G11: -10831.59 | I11: -10831.59 | J11: 10831.59 | L11: =IFERROR(ABS(K11),"") | M11: Only in GL | N11: =IF(J11>Summary!$B$18,"Yes","No") | O11: =RANK(J11,$J$2:$J$64,0)
A12: TXN-09023 | B12: 45337 | C12: Vendor Payment | D12: 5100 | E12: Vendor payment - materials | G12: -10519.65 | I12: -10519.65 | J12: 10519.65 | L12: =IFERROR(ABS(K12),"") | M12: Only in GL | N12: =IF(J12>Summary!$B$18,"Yes","No") | O12: =RANK(J12,$J$2:$J$64,0)
A13: TXN-09025 | B13: 45494 | C13: Vendor Payment | D13: 5100 | E13: Supplier invoice | G13: -10032.3 | I13: -10032.3 | J13: 10032.3 | L13: =IFERROR(ABS(K13),"") | M13: Only in GL | N13: =IF(J13>Summary!$B$18,"Yes","No") | O13: =RANK(J13,$J$2:$J$64,0)
A14: TXN-09019 | B14: 45386 | C14: Vendor Payment | D14: 5100 | E14: Supplier invoice | G14: -9548.1 | I14: -9548.1 | J14: 9548.1 | L14: =IFERROR(ABS(K14),"") | M14: Only in GL | N14: =IF(J14>Summary!$B$18,"Yes","No") | O14: =RANK(J14,$J$2:$J$64,0)
A15: TXN-09015 | B15: 45509 | C15: Payroll | D15: 6000 | E15: Monthly salary run | G15: -9535.87 | I15: -9535.87 | J15: 9535.87 | L15: =IFERROR(ABS(K15),"") | M15: Only in GL | N15: =IF(J15>Summary!$B$18,"Yes","No") | O15: =RANK(J15,$J$2:$J$64,0)
A16: TXN-09017 | B16: 45653 | C16: Payroll | D16: 6000 | E16: Monthly salary run | G16: -9119.86 | I16: -9119.86 | J16: 9119.86 | L16: =IFERROR(ABS(K16),"") | M16: Only in GL | N16: =IF(J16>Summary!$B$18,"Yes","No") | O16: =RANK(J16,$J$2:$J$64,0)
A17: TXN-09007 | B17: 45508 | C17: Payroll | D17: 6000 | E17: Payroll transfer | G17: -8659.91 | I17: -8659.91 | J17: 8659.91 | L17: =IFERROR(ABS(K17),"") | M17: Only in GL | N17: =IF(J17>Summary!$B$18,"Yes","No") | O17: =RANK(J17,$J$2:$J$64,0)
A18: TXN-09009 | B18: 45567 | C18: Payroll | D18: 6000 | E18: Payroll transfer | G18: -7143.09 | I18: -7143.09 | J18: 7143.09 | L18: =IFERROR(ABS(K18),"") | M18: Only in GL | N18: =IF(J18>Summary!$B$18,"Yes","No") | O18: =RANK(J18,$J$2:$J$64,0)
A19: TXN-00206 | B19: 45506 | C19: Payroll | D19: 6000 | E19: Employee wages | F19: EMPLOYEE WAGES | G19: -7023.64 | H19: -70.23 | I19: -7023.64 | J19: 7023.64 | K19: -6953.41 | L19: =IFERROR(ABS(K19),"") | M19: Amount Mismatch | N19: =IF(J19>Summary!$B$18,"Yes","No") | O19: =RANK(J19,$J$2:$J$64,0)
A20: TXN-00616 | B20: 45457 | C20: Rent | D20: 6100 | E20: Warehouse lease | F20: WAREHOUSE LEASE | G20: -5922.24 | H20: -5971.2 | I20: -5922.24 | J20: 5922.24 | K20: 48.96 | L20: =IFERROR(ABS(K20),"") | M20: Amount Mismatch | N20: =IF(J20>Summary!$B$18,"Yes","No") | O20: =RANK(J20,$J$2:$J$64,0)
A21: TXN-09024 | B21: 45434 | C21: Rent | D21: 6100 | E21: Monthly office rent | G21: -5776.25 | I21: -5776.25 | J21: 5776.25 | L21: =IFERROR(ABS(K21),"") | M21: Only in GL | N21: =IF(J21>Summary!$B$18,"Yes","No") | O21: =RANK(J21,$J$2:$J$64,0)
A22: TXN-09003 | B22: 45565 | C22: Rent | D22: 6100 | E22: Warehouse lease | G22: -4990.02 | I22: -4990.02 | J22: 4990.02 | L22: =IFERROR(ABS(K22),"") | M22: Only in GL | N22: =IF(J22>Summary!$B$18,"Yes","No") | O22: =RANK(J22,$J$2:$J$64,0)
A23: TXN-09006 | B23: 45602 | C23: Payroll | D23: 6000 | E23: Payroll transfer | G23: -4962.75 | I23: -4962.75 | J23: 4962.75 | L23: =IFERROR(ABS(K23),"") | M23: Only in GL | N23: =IF(J23>Summary!$B$18,"Yes","No") | O23: =RANK(J23,$J$2:$J$64,0)
A24: TXN-09005 | B24: 45318 | C24: Vendor Payment | D24: 5100 | E24: Vendor payment - materials | G24: -4601.7 | I24: -4601.7 | J24: 4601.7 | L24: =IFERROR(ABS(K24),"") | M24: Only in GL | N24: =IF(J24>Summary!$B$18,"Yes","No") | O24: =RANK(J24,$J$2:$J$64,0)
A25: TXN-09022 | B25: 45475 | C25: Rent | D25: 6100 | E25: Rent payment | G25: -3848.12 | I25: -3848.12 | J25: 3848.12 | L25: =IFERROR(ABS(K25),"") | M25: Only in GL | N25: =IF(J25>Summary!$B$18,"Yes","No") | O25: =RANK(J25,$J$2:$J$64,0)
A26: TXN-09012 | B26: 45496 | C26: Rent | D26: 6100 | E26: Monthly office rent | G26: -3543.71 | I26: -3543.71 | J26: 3543.71 | L26: =IFERROR(ABS(K26),"") | M26: Only in GL | N26: =IF(J26>Summary!$B$18,"Yes","No") | O26: =RANK(J26,$J$2:$J$64,0)
A27: TXN-09010 | B27: 45600 | C27: Rent | D27: 6100 | E27: Warehouse lease | G27: -3333 | I27: -3333 | J27: 3333 | L27: =IFERROR(ABS(K27),"") | M27: Only in GL | N27: =IF(J27>Summary!$B$18,"Yes","No") | O27: =RANK(J27,$J$2:$J$64,0)
A28: TXN-00789 | B28: 45293 | C28: Travel & Entertainment | D28: 6400 | E28: Client dinner | F28: CLIENT DINNER | G28: -3255.56 | H28: -32555.6 | I28: -3255.56 | J28: 3255.56 | K28: 29300.04 | L28: =IFERROR(ABS(K28),"") | M28: Amount Mismatch | N28: =IF(J28>Summary!$B$18,"Yes","No") | O28: =RANK(J28,$J$2:$J$64,0)
A29: TXN-09004 | B29: 45330 | C29: Rent | D29: 6100 | E29: Rent payment | G29: -2085.79 | I29: -2085.79 | J29: 2085.79 | L29: =IFERROR(ABS(K29),"") | M29: Only in GL | N29: =IF(J29>Summary!$B$18,"Yes","No") | O29: =RANK(J29,$J$2:$J$64,0)
A30: TXN-09014 | B30: 45403 | C30: Vendor Payment | D30: 5100 | E30: Supplier invoice | G30: -2032.89 | I30: -2032.89 | J30: 2032.89 | L30: =IFERROR(ABS(K30),"") | M30: Only in GL | N30: =IF(J30>Summary!$B$18,"Yes","No") | O30: =RANK(J30,$J$2:$J$64,0)
A31: TXN-09011 | B31: 45423 | C31: Rent | D31: 6100 | E31: Warehouse lease | G31: -2030.85 | I31: -2030.85 | J31: 2030.85 | L31: =IFERROR(ABS(K31),"") | M31: Only in GL | N31: =IF(J31>Summary!$B$18,"Yes","No") | O31: =RANK(J31,$J$2:$J$64,0)
A32: TXN-00641 | B32: 45560 | C32: Rent | D32: 6100 | E32: Monthly office rent | F32: MONTHLY OFFICE RENT | G32: -1728.74 | H32: -1316.02 | I32: -1728.74 | J32: 1728.74 | K32: -412.72 | L32: =IFERROR(ABS(K32),"") | M32: Amount Mismatch | N32: =IF(J32>Summary!$B$18,"Yes","No") | O32: =RANK(J32,$J$2:$J$64,0)
A33: TXN-09016 | B33: 45363 | C33: Vendor Payment | D33: 5100 | E33: Supplier invoice | G33: -1634.63 | I33: -1634.63 | J33: 1634.63 | L33: =IFERROR(ABS(K33),"") | M33: Only in GL | N33: =IF(J33>Summary!$B$18,"Yes","No") | O33: =RANK(J33,$J$2:$J$64,0)
A34: TXN-09018 | B34: 45646 | C34: Vendor Payment | D34: 5100 | E34: Contractor fee | G34: -1215.59 | I34: -1215.59 | J34: 1215.59 | L34: =IFERROR(ABS(K34),"") | M34: Only in GL | N34: =IF(J34>Summary!$B$18,"Yes","No") | O34: =RANK(J34,$J$2:$J$64,0)
A35: TXN-00245 | B35: 45483 | C35: Rent | D35: 6100 | E35: Rent payment | F35: RENT PAYMENT | G35: -937.97 | H35: -93.79 | I35: -937.97 | J35: 937.97 | K35: -844.18 | L35: =IFERROR(ABS(K35),"") | M35: Amount Mismatch | N35: =IF(J35>Summary!$B$18,"Yes","No") | O35: =RANK(J35,$J$2:$J$64,0)
A36: TXN-00871 | B36: 45406 | C36: Office Supplies | D36: 6300 | E36: Stationery purchase | F36: STATIONERY PURCHASE | G36: -820.62 | H36: -521.53 | I36: -820.62 | J36: 820.62 | K36: -299.09 | L36: =IFERROR(ABS(K36),"") | M36: Amount Mismatch | N36: =IF(J36>Summary!$B$18,"Yes","No") | O36: =RANK(J36,$J$2:$J$64,0)
A37: TXN-00770 | B37: 45480 | C37: Utilities | D37: 6200 | E37: Internet & telecom | F37: INTERNET & TELECOM | G37: -747.51 | H37: -689.45 | I37: -747.51 | J37: 747.51 | K37: -58.06 | L37: =IFERROR(ABS(K37),"") | M37: Amount Mismatch | N37: =IF(J37>Summary!$B$18,"Yes","No") | O37: =RANK(J37,$J$2:$J$64,0)
A38: TXN-00876 | B38: 45621 | C38: Travel & Entertainment | D38: 6400 | E38: Hotel accommodation | F38: HOTEL ACCOMMODATION | G38: -397.33 | H38: -284.39 | I38: -397.33 | J38: 397.33 | K38: -112.94 | L38: =IFERROR(ABS(K38),"") | M38: Amount Mismatch | N38: =IF(J38>Summary!$B$18,"Yes","No") | O38: =RANK(J38,$J$2:$J$64,0)
A39: TXN-00677 | B39: 45502 | C39: Travel & Entertainment | D39: 6400 | E39: Client dinner | F39: CLIENT DINNER | G39: -336.56 | H39: -3365.6 | I39: -336.56 | J39: 336.56 | K39: 3029.04 | L39: =IFERROR(ABS(K39),"") | M39: Amount Mismatch | N39: =IF(J39>Summary!$B$18,"Yes","No") | O39: =RANK(J39,$J$2:$J$64,0)
A40: TXN-09507 | B40: 45533 | C40: Unclassified (Bank only) | F40: INTEREST ACCRUAL | H40: 239.42 | I40: 239.42 | J40: 239.42 | L40: =IFERROR(ABS(K40),"") | M40: Only in Bank | N40: =IF(J40>Summary!$B$18,"Yes","No") | O40: =RANK(J40,$J$2:$J$64,0)
...

Sheet Reconciliation
A1: Transaction_ID | B1: Date | C1: Month | D1: Category | E1: Account | F1: Description_GL | G1: Description_Bank | H1: Amount_GL | I1: Amount_Bank | J1: Amount | K1: Abs_Amount | L1: Amount_Diff | M1: Status | N1: Is_Exception | O1: Has_Duplicate_ID
A2: TXN-00001 | B2: 45326 | C2: 45323 | D2: Sales Revenue | E2: 4000 | F2: Customer deposit | G2: CUSTOMER DEPOSIT | H2: 6585.96 | I2: 6585.96 | J2: 6585.96 | K2: 6585.96 | M2: Matched | N2: No | O2: No
A3: TXN-00002 | B3: 45403 | C3: 45383 | D3: Marketing | E3: 6500 | F3: Trade fair booth | G3: TRADE FAIR BOOTH | H3: -2071.65 | I3: -2071.65 | J3: -2071.65 | K3: 2071.65 | M3: Matched | N3: No | O3: No
A4: TXN-00003 | B4: 45516 | C4: 45505 | D4: Rent | E4: 6100 | F4: Monthly office rent | G4: MONTHLY OFFICE RENT | H4: -5688.1 | I4: -5688.1 | J4: -5688.1 | K4: 5688.1 | M4: Matched | N4: No | O4: No
A5: TXN-00004 | B5: 45448 | C5: 45444 | D5: Office Supplies | E5: 6300 | F5: Stationery purchase | G5: STATIONERY PURCHASE | H5: -801.43 | I5: -801.43 | J5: -801.43 | K5: 801.43 | M5: Matched | N5: No | O5: No
A6: TXN-00005 | B6: 45578 | C6: 45566 | D6: Office Supplies | E6: 6300 | F6: Stationery purchase | G6: STATIONERY PURCHASE | H6: -475.54 | I6: -475.54 | J6: -475.54 | K6: 475.54 | M6: Matched | N6: No | O6: No
A7: TXN-00006 | B7: 45515 | C7: 45505 | D7: Bank Fees | E7: 6900 | F7: Card processing fee | G7: CARD PROCESSING FEE | H7: -76.14 | I7: -76.14 | J7: -76.14 | K7: 76.14 | M7: Matched | N7: No | O7: No
A8: TXN-00007 | B8: 45438 | C8: 45413 | D8: Sales Revenue | E8: 4000 | F8: Customer deposit | G8: CUSTOMER DEPOSIT | H8: 13645.92 | I8: 13645.92 | J8: 13645.92 | K8: 13645.92 | M8: Matched | N8: No | O8: No
A9: TXN-00008 | B9: 45523 | C9: 45505 | D9: Rent | E9: 6100 | F9: Warehouse lease | G9: WAREHOUSE LEASE | H9: -3059.73 | I9: -3059.73 | J9: -3059.73 | K9: 3059.73 | M9: Matched | N9: No | O9: No
A10: TXN-00009 | B10: 45646 | C10: 45627 | D10: Payroll | E10: 6000 | F10: Payroll transfer | G10: PAYROLL TRANSFER | H10: -2819.47 | I10: -2819.47 | J10: -2819.47 | K10: 2819.47 | M10: Matched | N10: No | O10: No
A11: TXN-00010 | B11: 45442 | C11: 45413 | D11: Sales Revenue | E11: 4000 | F11: Invoice payment received | G11: INVOICE PAYMENT RECEIV | H11: 23830.12 | I11: 23830.12 | J11: 23830.12 | K11: 23830.12 | M11: Matched | N11: No | O11: No
A12: TXN-00011 | B12: 45348 | C12: 45323 | D12: Travel & Entertainment | E12: 6400 | F12: Business trip - airfare | G12: BUSINESS TRIP - AIRFAR | H12: -3339.96 | I12: -3339.96 | J12: -3339.96 | K12: 3339.96 | M12: Matched | N12: No | O12: No
A13: TXN-00012 | B13: 45441 | C13: 45413 | D13: Interest Income | E13: 4900 | F13: Savings interest | G13: SAVINGS INTEREST | H13: 69.61 | I13: 69.61 | J13: 69.61 | K13: 69.61 | M13: Matched | N13: No | O13: No
... A120: TXN-00119 | B120: 45413 | C120: 45413 | D120: Payroll | E120: 6000 | F120: Monthly salary run | G120: MONTHLY SALARY RUN | H120: -8353.21 | I120: -8353.21 | J120: -8353.21 | K120: 8353.21 | M120: Matched | N120: No | O120: No
A121: TXN-00120 | B121: 45295 | C121: 45292 | D121: Vendor Payment | E121: 5100 | F121: Contractor fee | G121: CONTRACTOR FEE | H121: -14882.22 | I121: -148822.2 | J121: -14882.22 | K121: 14882.22 | L121: 133939.98 | M121: Amount Mismatch | N121: Yes | O121: No
A122: TXN-00121 | B122: 45538 | C122: 45536 | D122: Office Supplies | E122: 6300 | F122: Stationery purchase | G122: STATIONERY PURCHASE | H122: -474.48 | I122: -474.48 | J122: -474.48 | K122: 474.48 | M122: Matched | N122: No | O122: No
A123: TXN-00122 | B123: 45368 | C123: 45352 | D123: Rent | E123: 6100 | F123: Rent payment | G123: RENT PAYMENT | H123: -1295.04 | I123: -1295.04 | J123: -1295.04 | K123: 1295.04 | M123: Matched | N123: No | O123: No
A124: TXN-00123 | B124: 45568 | C124: 45566 | D124: Rent | E124: 6100 | F124: Rent payment | G124: RENT PAYMENT | H124: -5878.65 | I124: -5878.65 | J124: -5878.65 | K124: 5878.65 | M124: Matched | N124: No | O124: No
A125: TXN-00124 | B125: 45483 | C125: 45474 | D125: Office Supplies | E125: 6300 | F125: Office equipment | G125: OFFICE EQUIPMENT | H125: -300.13 | I125: -300.13 | J125: -300.13 | K125: 300.13 | M125: Matched | N125: No | O125: No
A126: TXN-00125 | B126: 45462 | C126: 45444 | D126: Bank Fees | E126: 6900 | F126: Account maintenance fee | G126: ACCOUNT MAINTENANCE FE | H126: -66.59 | I126: -66.59 | J126: -66.59 | K126: 66.59 | M126: Matched | N126: No | O126: No
A127: TXN-00126 | B127: 45351 | C127: 45323 | D127: Travel & Entertainment | E127: 6400 | F127: Client dinner | G127: CLIENT DINNER | H127: -255.85 | I127: -255.85 | J127: -255.85 | K127: 255.85 | M127: Matched | N127: No | O127: No
A128: TXN-00127 | B128: 45551 | C128: 45536 | D128: Sales Revenue | E128: 4000 | F128: Customer deposit | G128: CUSTOMER DEPOSIT | H128: 9156.77 | I128: 9156.77 | J128: 9156.77 | K128: 9156.77 | M128: Matched | N128: No | O128: No
A129: TXN-00128 | B129: 45352 | C129: 45352 | D129: Marketing | E129: 6500 | F129: Print advertising | G129: PRINT ADVERTISING | H129: -6331.59 | I129: -6331.59 | J129: -6331.59 | K129: 6331.59 | M129: Matched | N129: No | O129: No
A130: TXN-00129 | B130: 45444 | C130: 45444 | D130: Travel & Entertainment | E130: 6400 | F130: Hotel accommodation | G130: HOTEL ACCOMMODATION | H130: -2888.61 | I130: -2888.61 | J130: -2888.61 | K130: 2888.61 | M130: Matched | N130: No | O130: No
A131: TXN-00130 | B131: 45597 | C131: 45597 | D131: Rent | E131: 6100 | F131: Rent payment | G131: RENT PAYMENT | H131: -2966.66 | I131: -2966.66 | J131: -2966.66 | K131: 2966.66 | M131: Matched | N131: No | O131: No
A132: TXN-00131 | B132: 45627 | C132: 45627 | D132: Travel & Entertainment | E132: 6400 | F132: Client dinner | G132: CLIENT DINNER | H132: -2640.97 | I132: -2640.97 | J132: -2640.97 | K132: 2640.97 | M132: Matched | N132: No | O132: No
A133: TXN-00132 | B133: 45653 | C133: 45627 | D133: Travel & Entertainment | E133: 6400 | F133: Business trip - airfare | G133: BUSINESS TRIP - AIRFAR | H133: -2820.75 | I133: -2820.75 | J133: -2820.75 | K133: 2820.75 | M133: Matched | N133: No | O133: No
... A166: TXN-00165 | B166: 45362 | C166: 45352 | D166: Office Supplies | E166: 6300 | F166: Printer consumables | G166: PRINTER CONSUMABLES | H166: -597.35 | I166: -597.35 | J166: -597.35 | K166: 597.35 | M166: Matched | N166: No | O166: No
A167: TXN-00166 | B167: 45470 | C167: 45444 | D167: Bank Fees | E167: 6900 | F167: Account maintenance fee | G167: ACCOUNT MAINTENANCE FE | H167: -46.92 | I167: -469.2 | J167: -46.92 | K167: 46.92 | L167: 422.28 | M167: Amount Mismatch | N167: Yes | O167: No
A168: TXN-00167 | B168: 45655 | C168: 45627 | D168: Utilities | E168: 6200 | F168: Electricity bill | G168: ELECTRICITY BILL | H168: -701.38 | I168: -701.38 | J168: -701.38 | K168: 701.38 | M168: Matched | N168: No | O168: No
A169: TXN-00168 | B169: 45506 | C169: 45505 | D169: Vendor Payment | E169: 5100 | F169: Contractor fee | G169: CONTRACTOR FEE | H169: -8353.45 | I169: -8353.45 | J169: -8353.45 | K169: 8353.45 | M169: Matched | N169: No | O169: No
A170: TXN-00169 | B170: 45555 | C170: 45536 | D170: Utilities | E170: 6200 | F170: Water utility | G170: WATER UTILITY | H170: -867.11 | I170: -867.11 | J170: -867.11 | K170: 867.11 | M170: Matched | N170: No | O170: No
A171: TXN-00170 | B171: 45472 | C171: 45444 | D171: Sales Revenue | E171: 4000 | F171: Product sale | G171: PRODUCT SALE | H171: 1151.16 | I171: 1151.16 | J171: 1151.16 | K171: 1151.16 | M171: Matched | N171: No | O171: No
A172: TXN-00171 | B172: 45297 | C172: 45292 | D172: Vendor Payment | E172: 5100 | F172: Vendor payment - materials | G172: VENDOR PAYMENT - MATER | H172: -9103.07 | I172: -9103.07 | J172: -9103.07 | K172: 9103.07 | M172: Matched | N172: No | O172: No
A173: TXN-00172 | B173: 45322 | C173: 45292 | D173: Sales Revenue | E173: 4000 | F173: Invoice payment received | G173: INVOICE PAYMENT RECEIV | H173: 12411.71 | I173: 12411.71 | J173: 12411.71 | K173: 12411.71 | M173: Matched | N173: No | O173: No
A174: TXN-00173 | B174: 45390 | C174: 45383 | D174: Marketing | E174: 6500 | F174: Trade fair booth | G174: TRADE FAIR BOOTH | H174: -3436.45 | I174: -3436.45 | J174: -3436.45 | K174: 3436.45 | M174: Matched | N174: No | O174: No
A175: TXN-00174 | B175: 45380 | C175: 45352 | D175: Marketing | E175: 6500 | F175: Online ad campaign | G175: ONLINE AD CAMPAIGN | H175: -6099.6 | I175: -6099.6 | J175: -6099.6 | K175: 6099.6 | M175: Matched | N175: No | O175: No
A176: TXN-00175 | B176: 45598 | C176: 45597 | D176: Rent | E176: 6100 | F176: Monthly office rent | G176: MONTHLY OFFICE RENT | H176: -3718.36 | I176: -3718.36 | J176: -3718.36 | K176: 3718.36 | M176: Matched | N176: No | O176: No
A177: TXN-00176 | B177: 45599 | C177: 45597 | D177: Office Supplies | E177: 6300 | F177: Office equipment | G177: OFFICE EQUIPMENT | H177: -359.13 | I177: -359.13 | J177: -359.13 | K177: 359.13 | M177: Matched | N177: No | O177: No
A178: TXN-00177 | B178: 45603 | C178: 45597 | D178: Marketing | E178: 6500 | F178: Print advertising | G178: PRINT ADVERTISING | H178: -4247.06 | I178: -4247.06 | J178: -4247.06 | K178: 4247.06 | M178: Matched | N178: No | O178: No
...

Sheet GL_Data
A1: Transaction_ID | B1: Date | C1: Description | D1: Category | E1: Amount | F1: Account | G1: Is_Duplicate
A2: TXN-00458 | B2: 45611 | C2: Rent payment | D2: Rent | E2: -2897.44 | F2: 6100 | G2: No
A3: TXN-00930 | B3: 45328 | C3: Hotel accommodation | D3: Travel & Entertainment | E3: -2555.21 | F3: 6400 | G3: No
A4: TXN-00330 | B4: 45607 | C4: Business trip - airfare | D4: Travel & Entertainment | E4: -747.32 | F4: 6400 | G4: No
A5: TXN-00350 | B5: 45302 | C5: Supplier invoice | D5: Vendor Payment | E5: -7889.33 | F5: 5100 | G5: No
A6: TXN-00784 | B6: 45607 | C6: Supplier invoice | D6: Vendor Payment | E6: -5900.48 | F6: 5100 | G6: No
A7: TXN-00134 | B7: 45494 | C7: Client dinner | D7: Travel & Entertainment | E7: -572.17 | F7: 6400 | G7: No
A8: TXN-00121 | B8: 45538 | C8: Stationery purchase | D8: Office Supplies | E8: -474.48 | F8: 6300 | G8: No
A9: TXN-00436 | B9: 45377 | C9: Supplier invoice | D9: Vendor Payment | E9: -12254.21 | F9: 5100 | G9: No
A10: TXN-00095 | B10: 45550 | C10: Wire transfer fee | D10: Bank Fees | E10: -46.95 | F10: 6900 | G10: No
A11: TXN-00763 | B11: 45613 | C11: Deposit interest credit | D11: Interest Income | E11: 360.54 | F11: 4900 | G11: No
A12: TXN-00456 | B12: 45348 | C12: Hotel accommodation | D12: Travel & Entertainment | E12: -2441.17 | F12: 6400 | G12: No
A13: TXN-00007 | B13: 45438 | C13: Customer deposit | D13: Sales Revenue | E13: 13645.92 | F13: 4000 | G13: No
... A982: TXN-00038 | B982: 45407 | C982: Wire transfer fee | D982: Bank Fees | E982: -138.67 | F982: 6900 | G982: No

Sheet Bank_Data
A1: Transaction_ID | B1: Date | C1: Description | D1: Amount | E1: Is_Duplicate
A2: TXN-00609 | B2: 45655 | C2: DEPOSIT INTEREST CREDI | D2: 213.08 | E2: No
A3: TXN-00398 | B3: 45548 | C3: VENDOR PAYMENT - MATER | D3: -3765.72 | E3: No
A4: TXN-00776 | B4: 45580 | C4: SAVINGS INTEREST | D4: 247.18 | E4: No
A5: TXN-00415 | B5: 45497 | C5: CUSTOMER DEPOSIT | D5: 14027.99 | E5: No
A6: TXN-00198 | B6: 45575 | C6: VENDOR PAYMENT - MATER | D6: -9235.18 | E6: No
A7: TXN-00526 | B7: 45405 | C7: INTERNET & TELECOM | D7: -660.99 | E7: No
A8: TXN-00766 | B8: 45615 | C8: ONLINE AD CAMPAIGN | D8: -1122.91 | E8: No
A9: TXN-00228 | B9: 45364 | C9: CLIENT DINNER | D9: -2332.94 | E9: No
A10: TXN-00820 | B10: 45364 | C10: INTEREST ACCRUAL | D10: 388.06 | E10: No
A11: TXN-00578 | B11: 45344 | C11: HOTEL ACCOMMODATION | D11: -2680.64 | E11: No
A12: TXN-00346 | B12: 45480 | C12: PAYROLL TRANSFER | D12: -9080.02 | E12: No
A13: TXN-00791 | B13: 45451 | C13: PRODUCT SALE | D13: 8207.25 | E13: No
... A975: TXN-00169 | B975: 45557 | C975: WATER UTILITY | D975: -867.11 | E975: No

Sheet Sheet1
A3: Row Labels | B3: Count of Transaction_ID | C3: Count of Transaction_ID2
A4: Matched | B4: 932 | C4: 0.93668342
A5: Only in GL | B5: 25 | C5: 0.025125628
A6: Only in Bank | B6: 20 | C6: 0.020100503
A7: Amount Mismatch | B7: 18 | C7: 0.018090452
A8: Grand Total | B8: 995 | C8: 1
A27: Sum of Abs_Amount | B27: Column Labels
A28: Row Labels | B28: No | C28: Yes | D28: Grand Total
A29: Sales Revenue | B29: 1078173.6 | C29: 18808.11 | D29: 1096981.7
A30: Vendor Payment | B30: 822259.99 | C30: 153310.68 | D30: 975570.67
A31: Payroll | B31: 532843.89 | C31: 46445.12 | D31: 579289.01
A32: Marketing | B32: 424140.85 | D32: 424140.85
A33: Rent | B33: 309720.48 | C33: 34196.69 | D33: 343917.17
A34: Travel & Entertainment | B34: 170228.14 | C34: 3989.45 | D34: 174217.59
A35: Office Supplies | B35: 52095.91 | C35: 1154.46 | D35: 53250.37
A36: Utilities | B36: 41177.74 | C36: 747.51 | D36: 41925.25
A37: Interest Income | B37: 21137.26 | D37: 21137.26
A38: Bank Fees | B38: 6585.07 | C38: 137.83 | D38: 6722.9
A39: Unclassified (Bank only) | C39: 2095.14 | D39: 2095.14
A40: Grand Total | B40: 3458362.9 | C40: 260884.99 | D40: 3719247.9
A47: Is_Exception | B47: Yes
A49: Row Labels | B49: Count of Transaction_ID
A50: 45292 | B50: 7
A51: 45323 | B51: 2
A52: 45352 | B52: 4
A53: 45383 | B53: 5
A54: 45413 | B54: 7
A55: 45444 | B55: 2
A56: 45474 | B56: 7
A57: 45505 | B57: 10
A58: 45536 | B58: 4
A59: 45566 | B59: 6
A60: 45597 | B60: 4
A61: 45627 | B61: 5
A62: Grand Total | B62: 63
